#####################################################################
2023-06-15 19:36:08.623520+09:00
카테고리는 java 로 하겠습니다.
주제는 SSE core task scheduler startup problem in eclipse 로 하겠습니다.
Traceback (most recent call last):
  File "/home/yoon/ChatGPT/ChatGPT-blog/main.py", line 120, in <module>
    title_response = generate_blog_to_title(topic)
  File "/home/yoon/ChatGPT/ChatGPT-blog/main.py", line 66, in generate_blog_to_title
    return generate_response(prompt, max_tokens=100, temperature=0.2)
  File "/home/yoon/ChatGPT/ChatGPT-blog/main.py", line 45, in generate_response
    completion = openai.ChatCompletion.create(
  File "/home/yoon/.local/lib/python3.10/site-packages/openai/api_resources/chat_completion.py", line 25, in create
    return super().create(*args, **kwargs)
  File "/home/yoon/.local/lib/python3.10/site-packages/openai/api_resources/abstract/engine_api_resource.py", line 153, in create
    response, _, api_key = requestor.request(
  File "/home/yoon/.local/lib/python3.10/site-packages/openai/api_requestor.py", line 226, in request
    resp, got_stream = self._interpret_response(result, stream)
  File "/home/yoon/.local/lib/python3.10/site-packages/openai/api_requestor.py", line 619, in _interpret_response
    self._interpret_response_line(
  File "/home/yoon/.local/lib/python3.10/site-packages/openai/api_requestor.py", line 682, in _interpret_response_line
    raise self.handle_error_response(
openai.error.AuthenticationError: <empty message>

During handling of the above exception, another exception occurred:

Traceback (most recent call last):
  File "/home/yoon/ChatGPT/ChatGPT-blog/main.py", line 126, in <module>
    print("title", title)
NameError: name 'title' is not defined. Did you mean: 'time'?
