#####################################################################
2023-06-15 19:32:05.213674+09:00
카테고리는 spring 로 하겠습니다.
주제는 Should Java JDBC Select statements always be in a Try-Catch block? 로 하겠습니다.
Traceback (most recent call last):
  File "/home/yoon/ChatGPT/ChatGPT-blog/main.py", line 120, in <module>
    title_response = generate_blog_to_title(topic)
  File "/home/yoon/ChatGPT/ChatGPT-blog/main.py", line 66, in generate_blog_to_title
    return generate_response(prompt, max_tokens=100, temperature=0.2)
  File "/home/yoon/ChatGPT/ChatGPT-blog/main.py", line 45, in generate_response
    completion = openai.ChatCompletion.create(
  File "/home/yoon/.local/lib/python3.10/site-packages/openai/api_resources/chat_completion.py", line 25, in create
    return super().create(*args, **kwargs)
  File "/home/yoon/.local/lib/python3.10/site-packages/openai/api_resources/abstract/engine_api_resource.py", line 153, in create
    response, _, api_key = requestor.request(
  File "/home/yoon/.local/lib/python3.10/site-packages/openai/api_requestor.py", line 226, in request
    resp, got_stream = self._interpret_response(result, stream)
  File "/home/yoon/.local/lib/python3.10/site-packages/openai/api_requestor.py", line 619, in _interpret_response
    self._interpret_response_line(
  File "/home/yoon/.local/lib/python3.10/site-packages/openai/api_requestor.py", line 682, in _interpret_response_line
    raise self.handle_error_response(
openai.error.AuthenticationError: <empty message>

During handling of the above exception, another exception occurred:

Traceback (most recent call last):
  File "/home/yoon/ChatGPT/ChatGPT-blog/main.py", line 126, in <module>
    print("title", title)
NameError: name 'title' is not defined. Did you mean: 'time'?
#####################################################################
2023-06-16 01:00:01.442169+09:00
카테고리는 spring 로 하겠습니다.
주제는 How to resolve &quot;could not execute statement; SQL [n/a]; nested exception is org.hibernate.exception.SQLGrammarException: could not execute statement&quot;? 로 하겠습니다.
제목 만들었습니다. Resolving the "Could Not Execute Statement; SQL [n/a]; Nested Exception is org.hibernate.exception.SQLGrammarException: Could Not Execute Statement" Error : 124
본문 1/2 만들었습니다. : 1240
본문 2/2 만들었습니다. : 1320
참고할만한 사이트를 만들었습니다. Resolving the "Could Not Execute Statement; SQL [n/a]; Nested Exception is org.hibernate.exception.SQLGrammarException: Could Not Execute Statement" Error : 508
파일을 생성하기 전 잠깐 기다립니다.
파일을 생성하겠습니다.
파일 생성 오류 발생 :  [Errno 2] No such file or directory: '/home/yoon/ChatGPT/ChatGPT-blog/_posts/2023-06-14-resolving-the-could-not-execute-statement;-sql-[n/a];-nested-exception-is-org.hibernate.exception.sqlgrammarexception:-could-not-execute-statement-error.md'
프로그램 종료.
#####################################################################
2023-06-16 07:00:02.098725+09:00
카테고리는 spring 로 하겠습니다.
주제는 LAZY Loading not working Spring Data 3.0.0 Hibernate - After Spring Boot Migration to 3.0 로 하겠습니다.
제목 만들었습니다. Resolving Lazy Loading Issues in Spring Data 3.0.0 Hibernate After Spring Boot Migration : 104
본문 1/2 만들었습니다. : 1241
본문 2/2 만들었습니다. : 1161
참고할만한 사이트를 만들었습니다. Resolving Lazy Loading Issues in Spring Data 3.0.0 Hibernate After Spring Boot Migration : 300
파일을 생성하기 전 잠깐 기다립니다.
파일을 생성하겠습니다.
모든 작업이 끝났습니다.
#####################################################################
#####################################################################
2023-06-17 09:00:01.689056+09:00
카테고리는 spring 로 하겠습니다.
주제는 404 error on Swagger UI with Spring (springdoc-openapi configuration) 로 하겠습니다.
제목 만들었습니다. Resolving 404 Error on Swagger UI with Spring: A Guide to Springdoc-Openapi Configuration : 96
본문 1/2 만들었습니다. : 1187
본문 2/2 만들었습니다. : 947
참고할만한 사이트를 만들었습니다. Resolving 404 Error on Swagger UI with Spring: A Guide to Springdoc-Openapi Configuration : 327
파일을 생성하기 전 잠깐 기다립니다.
파일을 생성하겠습니다.
모든 작업이 끝났습니다.
#####################################################################
#####################################################################
2023-06-17 11:00:01.798510+09:00
카테고리는 spring 로 하겠습니다.
주제는 Cannot resolve method &#39;antMatchers()&#39; in AuthorizationManagerRequestMatcherRegistry 로 하겠습니다.
제목 만들었습니다. Resolving 'antMatchers()' Method Error in AuthorizationManagerRequestMatcherRegistry : 93
본문 1/2 만들었습니다. : 1182
본문 2/2 만들었습니다. : 926
참고할만한 사이트를 만들었습니다. Resolving 'antMatchers()' Method Error in AuthorizationManagerRequestMatcherRegistry : 340
파일을 생성하기 전 잠깐 기다립니다.
파일을 생성하겠습니다.
모든 작업이 끝났습니다.
#####################################################################
#####################################################################
2023-06-19 07:00:01.783464+09:00
카테고리는 spring 로 하겠습니다.
주제는 LAZY Loading not working Spring Data 3.0.0 Hibernate - After Spring Boot Migration to 3.0 로 하겠습니다.
제목 만들었습니다. Resolving Lazy Loading Issues in Spring Data 3.0.0 Hibernate After Spring Boot Migration : 104
본문 1/2 만들었습니다. : 1164
본문 2/2 만들었습니다. : 1122
참고할만한 사이트를 만들었습니다. Resolving Lazy Loading Issues in Spring Data 3.0.0 Hibernate After Spring Boot Migration : 409
파일을 생성하기 전 잠깐 기다립니다.
파일을 생성하겠습니다.
모든 작업이 끝났습니다.
#####################################################################
#####################################################################
2023-06-20 07:00:02.226610+09:00
카테고리는 spring 로 하겠습니다.
주제는 How to resolve &quot;could not execute statement; SQL [n/a]; nested exception is org.hibernate.exception.SQLGrammarException: could not execute statement&quot;? 로 하겠습니다.
제목 만들었습니다. Resolving the "Could Not Execute Statement; SQL [n/a]; Nested Exception is org.hibernate.exception.SQLGrammarException: Could Not Execute Statement" Error : 124
본문 1/2 만들었습니다. : 1055
본문 2/2 만들었습니다. : 1114
참고할만한 사이트 생성 오류 발생 :  The server had an error while processing your request. Sorry about that! {
  "error": {
    "message": "The server had an error while processing your request. Sorry about that!",
    "type": "server_error",
    "param": null,
    "code": null
  }
}
 500 {'error': {'message': 'The server had an error while processing your request. Sorry about that!', 'type': 'server_error', 'param': None, 'code': None}} {'Date': 'Mon, 19 Jun 2023 22:04:28 GMT', 'Content-Type': 'application/json', 'Content-Length': '176', 'Connection': 'keep-alive', 'access-control-allow-origin': '*', 'openai-model': 'gpt-4-0613', 'openai-organization': 'user-cfljr7asc24pxittu0n11pgh', 'openai-processing-ms': '45', 'openai-version': '2020-10-01', 'strict-transport-security': 'max-age=15724800; includeSubDomains', 'x-ratelimit-limit-requests': '3000', 'x-ratelimit-limit-tokens': '250000', 'x-ratelimit-remaining-requests': '2999', 'x-ratelimit-remaining-tokens': '249484', 'x-ratelimit-reset-requests': '20ms', 'x-ratelimit-reset-tokens': '123ms', 'x-request-id': '2f947fa0dedced309069059377cdcac9', 'CF-Cache-Status': 'DYNAMIC', 'Server': 'cloudflare', 'CF-RAY': '7d9f1161fd89c06c-ICN', 'alt-svc': 'h3=":443"; ma=86400'}
프로그램 종료.
#####################################################################
2023-06-20 23:00:01.879198+09:00
카테고리는 spring 로 하겠습니다.
주제는 Defining additional placeholder/property only in beans.xml 로 하겠습니다.
제목 만들었습니다. "Understanding and Resolving Errors in Defining Additional Placeholder/Property in Beans.xml" : 88
본문 1/2 만들었습니다. : 894
본문 2/2 만들었습니다. : 1023
참고할만한 사이트를 만들었습니다. "Understanding and Resolving Errors in Defining Additional Placeholder/Property in Beans.xml" : 494
파일을 생성하기 전 잠깐 기다립니다.
파일을 생성하겠습니다.
파일 생성 오류 발생 :  [Errno 2] No such file or directory: '/home/yoon/ChatGPT/ChatGPT-blog/_posts/2023-06-19-understanding-and-resolving-errors-in-defining-additional-placeholder/property-in-beans.xml.md'
프로그램 종료.
#####################################################################
2023-06-23 11:00:01.506241+09:00
카테고리는 spring 로 하겠습니다.
주제는 Why does Spring Security 6 not create sessions when authenticating with curl and basic auth? 로 하겠습니다.
Traceback (most recent call last):
  File "/home/yoon/ChatGPT/ChatGPT-blog/main.py", line 120, in <module>
    title_response = generate_blog_to_title(topic)
  File "/home/yoon/ChatGPT/ChatGPT-blog/main.py", line 66, in generate_blog_to_title
    return generate_response(prompt, max_tokens=100, temperature=0.2)
  File "/home/yoon/ChatGPT/ChatGPT-blog/main.py", line 45, in generate_response
    completion = openai.ChatCompletion.create(
  File "/home/yoon/.local/lib/python3.10/site-packages/openai/api_resources/chat_completion.py", line 25, in create
    return super().create(*args, **kwargs)
  File "/home/yoon/.local/lib/python3.10/site-packages/openai/api_resources/abstract/engine_api_resource.py", line 153, in create
    response, _, api_key = requestor.request(
  File "/home/yoon/.local/lib/python3.10/site-packages/openai/api_requestor.py", line 226, in request
    resp, got_stream = self._interpret_response(result, stream)
  File "/home/yoon/.local/lib/python3.10/site-packages/openai/api_requestor.py", line 619, in _interpret_response
    self._interpret_response_line(
  File "/home/yoon/.local/lib/python3.10/site-packages/openai/api_requestor.py", line 682, in _interpret_response_line
    raise self.handle_error_response(
openai.error.RateLimitError: You exceeded your current quota, please check your plan and billing details.

During handling of the above exception, another exception occurred:

Traceback (most recent call last):
  File "/home/yoon/ChatGPT/ChatGPT-blog/main.py", line 126, in <module>
    print("title", title)
NameError: name 'title' is not defined. Did you mean: 'time'?
#####################################################################
2023-06-23 13:00:01.702354+09:00
카테고리는 spring 로 하겠습니다.
주제는 Should Java JDBC Select statements always be in a Try-Catch block? 로 하겠습니다.
Traceback (most recent call last):
  File "/home/yoon/ChatGPT/ChatGPT-blog/main.py", line 120, in <module>
    title_response = generate_blog_to_title(topic)
  File "/home/yoon/ChatGPT/ChatGPT-blog/main.py", line 66, in generate_blog_to_title
    return generate_response(prompt, max_tokens=100, temperature=0.2)
  File "/home/yoon/ChatGPT/ChatGPT-blog/main.py", line 45, in generate_response
    completion = openai.ChatCompletion.create(
  File "/home/yoon/.local/lib/python3.10/site-packages/openai/api_resources/chat_completion.py", line 25, in create
    return super().create(*args, **kwargs)
  File "/home/yoon/.local/lib/python3.10/site-packages/openai/api_resources/abstract/engine_api_resource.py", line 153, in create
    response, _, api_key = requestor.request(
  File "/home/yoon/.local/lib/python3.10/site-packages/openai/api_requestor.py", line 226, in request
    resp, got_stream = self._interpret_response(result, stream)
  File "/home/yoon/.local/lib/python3.10/site-packages/openai/api_requestor.py", line 619, in _interpret_response
    self._interpret_response_line(
  File "/home/yoon/.local/lib/python3.10/site-packages/openai/api_requestor.py", line 682, in _interpret_response_line
    raise self.handle_error_response(
openai.error.RateLimitError: You exceeded your current quota, please check your plan and billing details.

During handling of the above exception, another exception occurred:

Traceback (most recent call last):
  File "/home/yoon/ChatGPT/ChatGPT-blog/main.py", line 126, in <module>
    print("title", title)
NameError: name 'title' is not defined. Did you mean: 'time'?
#####################################################################
2023-06-23 21:00:01.492587+09:00
카테고리는 spring 로 하겠습니다.
주제는 LAZY Loading not working Spring Data 3.0.0 Hibernate - After Spring Boot Migration to 3.0 로 하겠습니다.
Traceback (most recent call last):
  File "/home/yoon/ChatGPT/ChatGPT-blog/main.py", line 120, in <module>
    title_response = generate_blog_to_title(topic)
  File "/home/yoon/ChatGPT/ChatGPT-blog/main.py", line 66, in generate_blog_to_title
    return generate_response(prompt, max_tokens=100, temperature=0.2)
  File "/home/yoon/ChatGPT/ChatGPT-blog/main.py", line 45, in generate_response
    completion = openai.ChatCompletion.create(
  File "/home/yoon/.local/lib/python3.10/site-packages/openai/api_resources/chat_completion.py", line 25, in create
    return super().create(*args, **kwargs)
  File "/home/yoon/.local/lib/python3.10/site-packages/openai/api_resources/abstract/engine_api_resource.py", line 153, in create
    response, _, api_key = requestor.request(
  File "/home/yoon/.local/lib/python3.10/site-packages/openai/api_requestor.py", line 226, in request
    resp, got_stream = self._interpret_response(result, stream)
  File "/home/yoon/.local/lib/python3.10/site-packages/openai/api_requestor.py", line 619, in _interpret_response
    self._interpret_response_line(
  File "/home/yoon/.local/lib/python3.10/site-packages/openai/api_requestor.py", line 682, in _interpret_response_line
    raise self.handle_error_response(
openai.error.RateLimitError: You exceeded your current quota, please check your plan and billing details.

During handling of the above exception, another exception occurred:

Traceback (most recent call last):
  File "/home/yoon/ChatGPT/ChatGPT-blog/main.py", line 126, in <module>
    print("title", title)
NameError: name 'title' is not defined. Did you mean: 'time'?
#####################################################################
2023-06-24 09:00:01.510682+09:00
카테고리는 spring 로 하겠습니다.
주제는 Register SPI dynamically at runtime 로 하겠습니다.
Traceback (most recent call last):
  File "/home/yoon/ChatGPT/ChatGPT-blog/main.py", line 120, in <module>
    title_response = generate_blog_to_title(topic)
  File "/home/yoon/ChatGPT/ChatGPT-blog/main.py", line 66, in generate_blog_to_title
    return generate_response(prompt, max_tokens=100, temperature=0.2)
  File "/home/yoon/ChatGPT/ChatGPT-blog/main.py", line 45, in generate_response
    completion = openai.ChatCompletion.create(
  File "/home/yoon/.local/lib/python3.10/site-packages/openai/api_resources/chat_completion.py", line 25, in create
    return super().create(*args, **kwargs)
  File "/home/yoon/.local/lib/python3.10/site-packages/openai/api_resources/abstract/engine_api_resource.py", line 153, in create
    response, _, api_key = requestor.request(
  File "/home/yoon/.local/lib/python3.10/site-packages/openai/api_requestor.py", line 226, in request
    resp, got_stream = self._interpret_response(result, stream)
  File "/home/yoon/.local/lib/python3.10/site-packages/openai/api_requestor.py", line 619, in _interpret_response
    self._interpret_response_line(
  File "/home/yoon/.local/lib/python3.10/site-packages/openai/api_requestor.py", line 682, in _interpret_response_line
    raise self.handle_error_response(
openai.error.RateLimitError: You exceeded your current quota, please check your plan and billing details.

During handling of the above exception, another exception occurred:

Traceback (most recent call last):
  File "/home/yoon/ChatGPT/ChatGPT-blog/main.py", line 126, in <module>
    print("title", title)
NameError: name 'title' is not defined. Did you mean: 'time'?
#####################################################################
2023-06-24 13:00:02.071774+09:00
카테고리는 spring 로 하겠습니다.
주제는 Why i have to add exclusion in spring-boot-maven-plugin while using LOMBOK? 로 하겠습니다.
Traceback (most recent call last):
  File "/home/yoon/ChatGPT/ChatGPT-blog/main.py", line 120, in <module>
    title_response = generate_blog_to_title(topic)
  File "/home/yoon/ChatGPT/ChatGPT-blog/main.py", line 66, in generate_blog_to_title
    return generate_response(prompt, max_tokens=100, temperature=0.2)
  File "/home/yoon/ChatGPT/ChatGPT-blog/main.py", line 45, in generate_response
    completion = openai.ChatCompletion.create(
  File "/home/yoon/.local/lib/python3.10/site-packages/openai/api_resources/chat_completion.py", line 25, in create
    return super().create(*args, **kwargs)
  File "/home/yoon/.local/lib/python3.10/site-packages/openai/api_resources/abstract/engine_api_resource.py", line 153, in create
    response, _, api_key = requestor.request(
  File "/home/yoon/.local/lib/python3.10/site-packages/openai/api_requestor.py", line 226, in request
    resp, got_stream = self._interpret_response(result, stream)
  File "/home/yoon/.local/lib/python3.10/site-packages/openai/api_requestor.py", line 619, in _interpret_response
    self._interpret_response_line(
  File "/home/yoon/.local/lib/python3.10/site-packages/openai/api_requestor.py", line 682, in _interpret_response_line
    raise self.handle_error_response(
openai.error.RateLimitError: You exceeded your current quota, please check your plan and billing details.

During handling of the above exception, another exception occurred:

Traceback (most recent call last):
  File "/home/yoon/ChatGPT/ChatGPT-blog/main.py", line 126, in <module>
    print("title", title)
NameError: name 'title' is not defined. Did you mean: 'time'?
#####################################################################
2023-06-24 23:00:02.283146+09:00
카테고리는 spring 로 하겠습니다.
주제는 Getting subsequent connections using HikariCP during same request seems slow 로 하겠습니다.
Traceback (most recent call last):
  File "/home/yoon/ChatGPT/ChatGPT-blog/main.py", line 120, in <module>
    title_response = generate_blog_to_title(topic)
  File "/home/yoon/ChatGPT/ChatGPT-blog/main.py", line 66, in generate_blog_to_title
    return generate_response(prompt, max_tokens=100, temperature=0.2)
  File "/home/yoon/ChatGPT/ChatGPT-blog/main.py", line 45, in generate_response
    completion = openai.ChatCompletion.create(
  File "/home/yoon/.local/lib/python3.10/site-packages/openai/api_resources/chat_completion.py", line 25, in create
    return super().create(*args, **kwargs)
  File "/home/yoon/.local/lib/python3.10/site-packages/openai/api_resources/abstract/engine_api_resource.py", line 153, in create
    response, _, api_key = requestor.request(
  File "/home/yoon/.local/lib/python3.10/site-packages/openai/api_requestor.py", line 226, in request
    resp, got_stream = self._interpret_response(result, stream)
  File "/home/yoon/.local/lib/python3.10/site-packages/openai/api_requestor.py", line 619, in _interpret_response
    self._interpret_response_line(
  File "/home/yoon/.local/lib/python3.10/site-packages/openai/api_requestor.py", line 682, in _interpret_response_line
    raise self.handle_error_response(
openai.error.RateLimitError: You exceeded your current quota, please check your plan and billing details.

During handling of the above exception, another exception occurred:

Traceback (most recent call last):
  File "/home/yoon/ChatGPT/ChatGPT-blog/main.py", line 126, in <module>
    print("title", title)
NameError: name 'title' is not defined. Did you mean: 'time'?
#####################################################################
2023-06-26 03:00:01.531014+09:00
카테고리는 spring 로 하겠습니다.
주제는 How to fix Spring authorizeRequests is deprecated? 로 하겠습니다.
Traceback (most recent call last):
  File "/home/yoon/ChatGPT/ChatGPT-blog/main.py", line 120, in <module>
    title_response = generate_blog_to_title(topic)
  File "/home/yoon/ChatGPT/ChatGPT-blog/main.py", line 66, in generate_blog_to_title
    return generate_response(prompt, max_tokens=100, temperature=0.2)
  File "/home/yoon/ChatGPT/ChatGPT-blog/main.py", line 45, in generate_response
    completion = openai.ChatCompletion.create(
  File "/home/yoon/.local/lib/python3.10/site-packages/openai/api_resources/chat_completion.py", line 25, in create
    return super().create(*args, **kwargs)
  File "/home/yoon/.local/lib/python3.10/site-packages/openai/api_resources/abstract/engine_api_resource.py", line 153, in create
    response, _, api_key = requestor.request(
  File "/home/yoon/.local/lib/python3.10/site-packages/openai/api_requestor.py", line 226, in request
    resp, got_stream = self._interpret_response(result, stream)
  File "/home/yoon/.local/lib/python3.10/site-packages/openai/api_requestor.py", line 619, in _interpret_response
    self._interpret_response_line(
  File "/home/yoon/.local/lib/python3.10/site-packages/openai/api_requestor.py", line 682, in _interpret_response_line
    raise self.handle_error_response(
openai.error.RateLimitError: You exceeded your current quota, please check your plan and billing details.

During handling of the above exception, another exception occurred:

Traceback (most recent call last):
  File "/home/yoon/ChatGPT/ChatGPT-blog/main.py", line 126, in <module>
    print("title", title)
NameError: name 'title' is not defined. Did you mean: 'time'?
