#####################################################################
2023-06-15 22:11:05.604037+09:00
카테고리는 python 로 하겠습니다.
주제는 How do I solve &quot;error: externally-managed-environment&quot; everytime I use pip3? 로 하겠습니다.
제목 만들었습니다. "Solving the 'Error: Externally-Managed-Environment' Issue in Pip3" : 102
본문 1/2 만들었습니다. : 1084
본문 2/2 만들었습니다. : 984
참고할만한 사이트를 만들었습니다. "Solving the 'Error: Externally-Managed-Environment' Issue in Pip3" : 241
파일을 생성하기 전 잠깐 기다립니다.
파일을 생성하겠습니다.
모든 작업이 끝났습니다.
#####################################################################
#####################################################################
2023-06-17 01:00:01.837596+09:00
카테고리는 python 로 하겠습니다.
주제는 AttributeError: partially initialized module &#39;cv2&#39; has no attribute &#39;gapi_wip_gst_GStreamerPipeline&#39; (most likely due to a circular import) 로 하겠습니다.
제목 만들었습니다. Resolving the 'cv2' Module AttributeError in Python : 112
본문 1/2 만들었습니다. : 1113
본문 2/2 만들었습니다. : 988
참고할만한 사이트를 만들었습니다. Resolving the 'cv2' Module AttributeError in Python : 334
파일을 생성하기 전 잠깐 기다립니다.
파일을 생성하겠습니다.
모든 작업이 끝났습니다.
#####################################################################
#####################################################################
2023-06-17 05:00:01.328522+09:00
카테고리는 python 로 하겠습니다.
주제는 How to reference a requirements.txt in the pyproject.toml of a setuptools project? 로 하겠습니다.
제목 만들었습니다. "Resolving Requirements.txt Reference Error in Pyproject.toml of a Setuptools Project" : 96
본문 1/2 만들었습니다. : 1005
본문 2/2 만들었습니다. : 1092
참고할만한 사이트를 만들었습니다. "Resolving Requirements.txt Reference Error in Pyproject.toml of a Setuptools Project" : 332
파일을 생성하기 전 잠깐 기다립니다.
파일을 생성하겠습니다.
모든 작업이 끝났습니다.
#####################################################################
#####################################################################
2023-06-18 01:00:01.707778+09:00
카테고리는 python 로 하겠습니다.
주제는 Selenium - Python - AttributeError: &#39;WebDriver&#39; object has no attribute &#39;find_element_by_name&#39; 로 하겠습니다.
제목 만들었습니다. Resolving AttributeError in Selenium Python: 'WebDriver' Object Missing 'find_element_by_name' Attribute : 107
본문 1/2 만들었습니다. : 1092
본문 2/2 만들었습니다. : 911
참고할만한 사이트를 만들었습니다. Resolving AttributeError in Selenium Python: 'WebDriver' Object Missing 'find_element_by_name' Attribute : 288
파일을 생성하기 전 잠깐 기다립니다.
파일을 생성하겠습니다.
모든 작업이 끝났습니다.
#####################################################################
#####################################################################
2023-06-19 03:00:01.666668+09:00
카테고리는 python 로 하겠습니다.
주제는 Selenium - Python - AttributeError: &#39;WebDriver&#39; object has no attribute &#39;find_element_by_name&#39; 로 하겠습니다.
제목 만들었습니다. Resolving AttributeError in Selenium Python: 'WebDriver' Object Missing 'find_element_by_name' Attribute : 107
본문 1/2 만들었습니다. : 1377
본문 2/2 만들었습니다. : 1171
참고할만한 사이트를 만들었습니다. Resolving AttributeError in Selenium Python: 'WebDriver' Object Missing 'find_element_by_name' Attribute : 262
파일을 생성하기 전 잠깐 기다립니다.
파일을 생성하겠습니다.
모든 작업이 끝났습니다.
#####################################################################
#####################################################################
2023-06-19 15:00:01.572340+09:00
카테고리는 python 로 하겠습니다.
주제는 How do I solve &quot;error: externally-managed-environment&quot; everytime I use pip3? 로 하겠습니다.
제목 만들었습니다. "Solving the 'Error: Externally-Managed-Environment' Issue in Pip3" : 102
본문 1/2 만들었습니다. : 980
본문 2/2 만들었습니다. : 873
참고할만한 사이트를 만들었습니다. "Solving the 'Error: Externally-Managed-Environment' Issue in Pip3" : 213
파일을 생성하기 전 잠깐 기다립니다.
파일을 생성하겠습니다.
모든 작업이 끝났습니다.
#####################################################################
#####################################################################
2023-06-20 03:00:01.412120+09:00
카테고리는 python 로 하겠습니다.
주제는 OpenAI ChatGPT (GPT-3.5) API error 429: &quot;You exceeded your current quota, please check your plan and billing details&quot; 로 하겠습니다.
제목 만들었습니다. "Understanding and Resolving the OpenAI ChatGPT API Error 429" : 113
본문 1/2 만들었습니다. : 1575
본문 오류발생 :  HTTP code 502 from API (<html>
<head><title>502 Bad Gateway</title></head>
<body>
<center><h1>502 Bad Gateway</h1></center>
<hr><center>cloudflare</center>
</body>
</html>
)
프로그램 종료.
#####################################################################
2023-06-20 17:00:01.871937+09:00
카테고리는 python 로 하겠습니다.
주제는 OpenAI ChatGPT (GPT-3.5) API error 429: &quot;You exceeded your current quota, please check your plan and billing details&quot; 로 하겠습니다.
제목 만들었습니다. "Understanding and Resolving the OpenAI ChatGPT API Error 429" : 113
본문 오류발생 :  The server had an error while processing your request. Sorry about that! {
  "error": {
    "message": "The server had an error while processing your request. Sorry about that!",
    "type": "server_error",
    "param": null,
    "code": null
  }
}
 500 {'error': {'message': 'The server had an error while processing your request. Sorry about that!', 'type': 'server_error', 'param': None, 'code': None}} {'Date': 'Tue, 20 Jun 2023 08:00:13 GMT', 'Content-Type': 'application/json', 'Content-Length': '176', 'Connection': 'keep-alive', 'access-control-allow-origin': '*', 'openai-model': 'gpt-4-0613', 'openai-organization': 'user-cfljr7asc24pxittu0n11pgh', 'openai-processing-ms': '31', 'openai-version': '2020-10-01', 'strict-transport-security': 'max-age=15724800; includeSubDomains', 'x-ratelimit-limit-requests': '3000', 'x-ratelimit-limit-tokens': '250000', 'x-ratelimit-remaining-requests': '2999', 'x-ratelimit-remaining-tokens': '247217', 'x-ratelimit-reset-requests': '20ms', 'x-ratelimit-reset-tokens': '667ms', 'x-request-id': '90f5b3d58c8c62c6a1d7202820367db1', 'CF-Cache-Status': 'DYNAMIC', 'Server': 'cloudflare', 'CF-RAY': '7da27a124ae4a7b4-ICN', 'alt-svc': 'h3=":443"; ma=86400'}
프로그램 종료.
#####################################################################
2023-06-21 17:00:01.712361+09:00
카테고리는 python 로 하겠습니다.
주제는 Unexpected uint64 behaviour 0xFFFF&#39;FFFF&#39;FFFF&#39;FFFF - 1 = 0? 로 하겠습니다.
Traceback (most recent call last):
  File "/home/yoon/ChatGPT/ChatGPT-blog/main.py", line 120, in <module>
    title_response = generate_blog_to_title(topic)
  File "/home/yoon/ChatGPT/ChatGPT-blog/main.py", line 66, in generate_blog_to_title
    return generate_response(prompt, max_tokens=100, temperature=0.2)
  File "/home/yoon/ChatGPT/ChatGPT-blog/main.py", line 45, in generate_response
    completion = openai.ChatCompletion.create(
  File "/home/yoon/.local/lib/python3.10/site-packages/openai/api_resources/chat_completion.py", line 25, in create
    return super().create(*args, **kwargs)
  File "/home/yoon/.local/lib/python3.10/site-packages/openai/api_resources/abstract/engine_api_resource.py", line 153, in create
    response, _, api_key = requestor.request(
  File "/home/yoon/.local/lib/python3.10/site-packages/openai/api_requestor.py", line 226, in request
    resp, got_stream = self._interpret_response(result, stream)
  File "/home/yoon/.local/lib/python3.10/site-packages/openai/api_requestor.py", line 619, in _interpret_response
    self._interpret_response_line(
  File "/home/yoon/.local/lib/python3.10/site-packages/openai/api_requestor.py", line 682, in _interpret_response_line
    raise self.handle_error_response(
openai.error.APIError: The server had an error while processing your request. Sorry about that! {
  "error": {
    "message": "The server had an error while processing your request. Sorry about that!",
    "type": "server_error",
    "param": null,
    "code": null
  }
}
 500 {'error': {'message': 'The server had an error while processing your request. Sorry about that!', 'type': 'server_error', 'param': None, 'code': None}} {'Date': 'Wed, 21 Jun 2023 08:00:12 GMT', 'Content-Type': 'application/json', 'Content-Length': '176', 'Connection': 'keep-alive', 'access-control-allow-origin': '*', 'openai-model': 'gpt-4-0613', 'openai-organization': 'user-cfljr7asc24pxittu0n11pgh', 'openai-processing-ms': '273', 'openai-version': '2020-10-01', 'strict-transport-security': 'max-age=15724800; includeSubDomains', 'x-ratelimit-limit-requests': '3000', 'x-ratelimit-limit-tokens': '250000', 'x-ratelimit-remaining-requests': '2999', 'x-ratelimit-remaining-tokens': '249828', 'x-ratelimit-reset-requests': '20ms', 'x-ratelimit-reset-tokens': '41ms', 'x-request-id': 'fb4cf9341eed3334c7ffedc05879ac61', 'CF-Cache-Status': 'DYNAMIC', 'Server': 'cloudflare', 'CF-RAY': '7daab76c6f3fc06c-ICN', 'alt-svc': 'h3=":443"; ma=86400'}

During handling of the above exception, another exception occurred:

Traceback (most recent call last):
  File "/home/yoon/ChatGPT/ChatGPT-blog/main.py", line 126, in <module>
    print("title", title)
NameError: name 'title' is not defined. Did you mean: 'time'?
#####################################################################
2023-06-22 05:00:01.767041+09:00
카테고리는 python 로 하겠습니다.
주제는 Heroku postgres postgis - django releases fail with: relation &quot;spatial_ref_sys&quot; does not exist 로 하겠습니다.
제목 만들었습니다. "Solving the 'Relation Spatial_ref_sys Does Not Exist' Error in Heroku Postgres PostGIS with Django" : 108
본문 1/2 만들었습니다. : 1503
본문 2/2 만들었습니다. : 1364
참고할만한 사이트를 만들었습니다. "Solving the 'Relation Spatial_ref_sys Does Not Exist' Error in Heroku Postgres PostGIS with Django" : 326
파일을 생성하기 전 잠깐 기다립니다.
파일을 생성하겠습니다.
모든 작업이 끝났습니다.
#####################################################################
#####################################################################
2023-06-24 07:00:01.630054+09:00
카테고리는 python 로 하겠습니다.
StackAPI 오류발생 :  list index out of range
프로그램 종료.
#####################################################################
2023-06-24 21:00:01.908057+09:00
카테고리는 python 로 하겠습니다.
주제는 yield from vs yield in for-loop 로 하겠습니다.
Traceback (most recent call last):
  File "/home/yoon/ChatGPT/ChatGPT-blog/main.py", line 120, in <module>
    title_response = generate_blog_to_title(topic)
  File "/home/yoon/ChatGPT/ChatGPT-blog/main.py", line 66, in generate_blog_to_title
    return generate_response(prompt, max_tokens=100, temperature=0.2)
  File "/home/yoon/ChatGPT/ChatGPT-blog/main.py", line 45, in generate_response
    completion = openai.ChatCompletion.create(
  File "/home/yoon/.local/lib/python3.10/site-packages/openai/api_resources/chat_completion.py", line 25, in create
    return super().create(*args, **kwargs)
  File "/home/yoon/.local/lib/python3.10/site-packages/openai/api_resources/abstract/engine_api_resource.py", line 153, in create
    response, _, api_key = requestor.request(
  File "/home/yoon/.local/lib/python3.10/site-packages/openai/api_requestor.py", line 226, in request
    resp, got_stream = self._interpret_response(result, stream)
  File "/home/yoon/.local/lib/python3.10/site-packages/openai/api_requestor.py", line 619, in _interpret_response
    self._interpret_response_line(
  File "/home/yoon/.local/lib/python3.10/site-packages/openai/api_requestor.py", line 682, in _interpret_response_line
    raise self.handle_error_response(
openai.error.RateLimitError: You exceeded your current quota, please check your plan and billing details.

During handling of the above exception, another exception occurred:

Traceback (most recent call last):
  File "/home/yoon/ChatGPT/ChatGPT-blog/main.py", line 126, in <module>
    print("title", title)
NameError: name 'title' is not defined. Did you mean: 'time'?
#####################################################################
2023-06-25 23:00:01.375888+09:00
카테고리는 python 로 하겠습니다.
주제는 Unexpected uint64 behaviour 0xFFFF&#39;FFFF&#39;FFFF&#39;FFFF - 1 = 0? 로 하겠습니다.
Traceback (most recent call last):
  File "/home/yoon/ChatGPT/ChatGPT-blog/main.py", line 120, in <module>
    title_response = generate_blog_to_title(topic)
  File "/home/yoon/ChatGPT/ChatGPT-blog/main.py", line 66, in generate_blog_to_title
    return generate_response(prompt, max_tokens=100, temperature=0.2)
  File "/home/yoon/ChatGPT/ChatGPT-blog/main.py", line 45, in generate_response
    completion = openai.ChatCompletion.create(
  File "/home/yoon/.local/lib/python3.10/site-packages/openai/api_resources/chat_completion.py", line 25, in create
    return super().create(*args, **kwargs)
  File "/home/yoon/.local/lib/python3.10/site-packages/openai/api_resources/abstract/engine_api_resource.py", line 153, in create
    response, _, api_key = requestor.request(
  File "/home/yoon/.local/lib/python3.10/site-packages/openai/api_requestor.py", line 226, in request
    resp, got_stream = self._interpret_response(result, stream)
  File "/home/yoon/.local/lib/python3.10/site-packages/openai/api_requestor.py", line 619, in _interpret_response
    self._interpret_response_line(
  File "/home/yoon/.local/lib/python3.10/site-packages/openai/api_requestor.py", line 682, in _interpret_response_line
    raise self.handle_error_response(
openai.error.RateLimitError: You exceeded your current quota, please check your plan and billing details.

During handling of the above exception, another exception occurred:

Traceback (most recent call last):
  File "/home/yoon/ChatGPT/ChatGPT-blog/main.py", line 126, in <module>
    print("title", title)
NameError: name 'title' is not defined. Did you mean: 'time'?
#####################################################################
2023-06-26 01:00:01.383569+09:00
카테고리는 python 로 하겠습니다.
주제는 &#39;EntryPoints&#39; object has no attribute &#39;get&#39; - Digital ocean 로 하겠습니다.
Traceback (most recent call last):
  File "/home/yoon/ChatGPT/ChatGPT-blog/main.py", line 120, in <module>
    title_response = generate_blog_to_title(topic)
  File "/home/yoon/ChatGPT/ChatGPT-blog/main.py", line 66, in generate_blog_to_title
    return generate_response(prompt, max_tokens=100, temperature=0.2)
  File "/home/yoon/ChatGPT/ChatGPT-blog/main.py", line 45, in generate_response
    completion = openai.ChatCompletion.create(
  File "/home/yoon/.local/lib/python3.10/site-packages/openai/api_resources/chat_completion.py", line 25, in create
    return super().create(*args, **kwargs)
  File "/home/yoon/.local/lib/python3.10/site-packages/openai/api_resources/abstract/engine_api_resource.py", line 153, in create
    response, _, api_key = requestor.request(
  File "/home/yoon/.local/lib/python3.10/site-packages/openai/api_requestor.py", line 226, in request
    resp, got_stream = self._interpret_response(result, stream)
  File "/home/yoon/.local/lib/python3.10/site-packages/openai/api_requestor.py", line 619, in _interpret_response
    self._interpret_response_line(
  File "/home/yoon/.local/lib/python3.10/site-packages/openai/api_requestor.py", line 682, in _interpret_response_line
    raise self.handle_error_response(
openai.error.RateLimitError: You exceeded your current quota, please check your plan and billing details.

During handling of the above exception, another exception occurred:

Traceback (most recent call last):
  File "/home/yoon/ChatGPT/ChatGPT-blog/main.py", line 126, in <module>
    print("title", title)
NameError: name 'title' is not defined. Did you mean: 'time'?
#####################################################################
2023-06-26 09:00:01.641902+09:00
카테고리는 python 로 하겠습니다.
주제는 Combine multiple columns into one category column using the column names as value label 로 하겠습니다.
Traceback (most recent call last):
  File "/home/yoon/ChatGPT/ChatGPT-blog/main.py", line 120, in <module>
    title_response = generate_blog_to_title(topic)
  File "/home/yoon/ChatGPT/ChatGPT-blog/main.py", line 66, in generate_blog_to_title
    return generate_response(prompt, max_tokens=100, temperature=0.2)
  File "/home/yoon/ChatGPT/ChatGPT-blog/main.py", line 45, in generate_response
    completion = openai.ChatCompletion.create(
  File "/home/yoon/.local/lib/python3.10/site-packages/openai/api_resources/chat_completion.py", line 25, in create
    return super().create(*args, **kwargs)
  File "/home/yoon/.local/lib/python3.10/site-packages/openai/api_resources/abstract/engine_api_resource.py", line 153, in create
    response, _, api_key = requestor.request(
  File "/home/yoon/.local/lib/python3.10/site-packages/openai/api_requestor.py", line 226, in request
    resp, got_stream = self._interpret_response(result, stream)
  File "/home/yoon/.local/lib/python3.10/site-packages/openai/api_requestor.py", line 619, in _interpret_response
    self._interpret_response_line(
  File "/home/yoon/.local/lib/python3.10/site-packages/openai/api_requestor.py", line 682, in _interpret_response_line
    raise self.handle_error_response(
openai.error.RateLimitError: You exceeded your current quota, please check your plan and billing details.

During handling of the above exception, another exception occurred:

Traceback (most recent call last):
  File "/home/yoon/ChatGPT/ChatGPT-blog/main.py", line 126, in <module>
    print("title", title)
NameError: name 'title' is not defined. Did you mean: 'time'?
